Workbook

Sheet READ ME
A1: Instaprotek Portal - Regression QA Log
A2: Your test cases, one sheet per module, set up for logging results. This workbook is the QA log.
A4: How to log a run
A5: 1. Copy this workbook per release, e.g. Regression_QA_Log_<version>.xlsx.
A6: 2. In each module sheet set the 'Actual Result' column to Pass / Fail / Blocked / Not Tested / N/A (dropdown); put detail in 'Notes/Remarks'.
A7: 3. For any Fail, add a row on the DEFECT LOG tab and put its Defect ID in the 'Defect ID' column of the test row.
A8: 4. The SUMMARY tab totals pass/fail per module and overall automatically.
A10: Environment & login
A11: Test on QA-environment (qa.crm.instaprotek.com) with the QA login in credentials.json. Delete any test records you create when done - never against Production.
A13: Test data (registration)
A14: Product barcode to use: 810135810326
A15: Example device from past runs: Samsung, Model SM-A156UZKDXAA. Use a QA/test serial number and delete the record after testing.

Sheet SUMMARY
A1: Regression QA Log - Summary
A3: Total cases | B3: =B31 | D3: Pass rate (of executed) | E3: =IFERROR(C31/(C31+D31+E31),0)
A4: Executed | B4: =C31+D31+E31
A6: Module | B6: Total | C6: Pass | D6: Fail | E6: Blocked | F6: Not Tested | G6: N/A
A7: USERS | B7: =COUNTA(USERS!$B$2:$B$2000) | C7: =COUNTIF(USERS!$E$2:$E$2000,"Pass") | D7: =COUNTIF(USERS!$E$2:$E$2000,"Fail") | E7: =COUNTIF(USERS!$E$2:$E$2000,"Blocked") | F7: =COUNTIF(USERS!$E$2:$E$2000,"Not Tested") | G7: =COUNTIF(USERS!$E$2:$E$2000,"N/A")
A8: PORTAL - REGISTRATION | B8: =COUNTA('PORTAL - REGISTRATION'!$B$2:$B$2000) | C8: =COUNTIF('PORTAL - REGISTRATION'!$E$2:$E$2000,"Pass") | D8: =COUNTIF('PORTAL - REGISTRATION'!$E$2:$E$2000,"Fail") | E8: =COUNTIF('PORTAL - REGISTRATION'!$E$2:$E$2000,"Blocked") | F8: =COUNTIF('PORTAL - REGISTRATION'!$E$2:$E$2000,"Not Tested") | G8: =COUNTIF('PORTAL - REGISTRATION'!$E$2:$E$2000,"N/A")
A9: ORDERS | B9: =COUNTA(ORDERS!$B$2:$B$2000) | C9: =COUNTIF(ORDERS!$E$2:$E$2000,"Pass") | D9: =COUNTIF(ORDERS!$E$2:$E$2000,"Fail") | E9: =COUNTIF(ORDERS!$E$2:$E$2000,"Blocked") | F9: =COUNTIF(ORDERS!$E$2:$E$2000,"Not Tested") | G9: =COUNTIF(ORDERS!$E$2:$E$2000,"N/A")
A10: REPAIR SHOPS | B10: =COUNTA('REPAIR SHOPS'!$B$2:$B$2000) | C10: =COUNTIF('REPAIR SHOPS'!$E$2:$E$2000,"Pass") | D10: =COUNTIF('REPAIR SHOPS'!$E$2:$E$2000,"Fail") | E10: =COUNTIF('REPAIR SHOPS'!$E$2:$E$2000,"Blocked") | F10: =COUNTIF('REPAIR SHOPS'!$E$2:$E$2000,"Not Tested") | G10: =COUNTIF('REPAIR SHOPS'!$E$2:$E$2000,"N/A")
A11: AFFILIATES | B11: =COUNTA(AFFILIATES!$B$2:$B$2000) | C11: =COUNTIF(AFFILIATES!$E$2:$E$2000,"Pass") | D11: =COUNTIF(AFFILIATES!$E$2:$E$2000,"Fail") | E11: =COUNTIF(AFFILIATES!$E$2:$E$2000,"Blocked") | F11: =COUNTIF(AFFILIATES!$E$2:$E$2000,"Not Tested") | G11: =COUNTIF(AFFILIATES!$E$2:$E$2000,"N/A")
A12: CLAIM REPORTS | B12: =COUNTA('CLAIM REPORTS'!$B$2:$B$2000) | C12: =COUNTIF('CLAIM REPORTS'!$E$2:$E$2000,"Pass") | D12: =COUNTIF('CLAIM REPORTS'!$E$2:$E$2000,"Fail") | E12: =COUNTIF('CLAIM REPORTS'!$E$2:$E$2000,"Blocked") | F12: =COUNTIF('CLAIM REPORTS'!$E$2:$E$2000,"Not Tested") | G12: =COUNTIF('CLAIM REPORTS'!$E$2:$E$2000,"N/A")
A13: PRODUCT REVIEWS | B13: =COUNTA('PRODUCT REVIEWS'!$B$2:$B$2000) | C13: =COUNTIF('PRODUCT REVIEWS'!$E$2:$E$2000,"Pass") | D13: =COUNTIF('PRODUCT REVIEWS'!$E$2:$E$2000,"Fail") | E13: =COUNTIF('PRODUCT REVIEWS'!$E$2:$E$2000,"Blocked") | F13: =COUNTIF('PRODUCT REVIEWS'!$E$2:$E$2000,"Not Tested") | G13: =COUNTIF('PRODUCT REVIEWS'!$E$2:$E$2000,"N/A")
A14: DEVICE BUYBACK | B14: =COUNTA('DEVICE BUYBACK'!$B$2:$B$2000) | C14: =COUNTIF('DEVICE BUYBACK'!$E$2:$E$2000,"Pass") | D14: =COUNTIF('DEVICE BUYBACK'!$E$2:$E$2000,"Fail") | E14: =COUNTIF('DEVICE BUYBACK'!$E$2:$E$2000,"Blocked") | F14: =COUNTIF('DEVICE BUYBACK'!$E$2:$E$2000,"Not Tested") | G14: =COUNTIF('DEVICE BUYBACK'!$E$2:$E$2000,"N/A")
A15: SETTINGS - DEVICE CATEGORY | B15: =COUNTA('SETTINGS - DEVICE CATEGORY'!$B$2:$B$2000) | C15: =COUNTIF('SETTINGS - DEVICE CATEGORY'!$E$2:$E$2000,"Pass") | D15: =COUNTIF('SETTINGS - DEVICE CATEGORY'!$E$2:$E$2000,"Fail") | E15: =COUNTIF('SETTINGS - DEVICE CATEGORY'!$E$2:$E$2000,"Blocked") | F15: =COUNTIF('SETTINGS - DEVICE CATEGORY'!$E$2:$E$2000,"Not Tested") | G15: =COUNTIF('SETTINGS - DEVICE CATEGORY'!$E$2:$E$2000,"N/A")
A16: SETTINGS - PRODUCT CATEGORY | B16: =COUNTA('SETTINGS - PRODUCT CATEGORY '!$B$2:$B$2000) | C16: =COUNTIF('SETTINGS - PRODUCT CATEGORY '!$E$2:$E$2000,"Pass") | D16: =COUNTIF('SETTINGS - PRODUCT CATEGORY '!$E$2:$E$2000,"Fail") | E16: =COUNTIF('SETTINGS - PRODUCT CATEGORY '!$E$2:$E$2000,"Blocked") | F16: =COUNTIF('SETTINGS - PRODUCT CATEGORY '!$E$2:$E$2000,"Not Tested") | G16: =COUNTIF('SETTINGS - PRODUCT CATEGORY '!$E$2:$E$2000,"N/A")
A17: SETTINGS - BRAND | B17: =COUNTA('SETTINGS - BRAND'!$B$2:$B$2000) | C17: =COUNTIF('SETTINGS - BRAND'!$E$2:$E$2000,"Pass") | D17: =COUNTIF('SETTINGS - BRAND'!$E$2:$E$2000,"Fail") | E17: =COUNTIF('SETTINGS - BRAND'!$E$2:$E$2000,"Blocked") | F17: =COUNTIF('SETTINGS - BRAND'!$E$2:$E$2000,"Not Tested") | G17: =COUNTIF('SETTINGS - BRAND'!$E$2:$E$2000,"N/A")
A18: SETTINGS - REGISTRATION SURVEY | B18: =COUNTA('SETTINGS - REGISTRATION SURVEY '!$B$2:$B$2000) | C18: =COUNTIF('SETTINGS - REGISTRATION SURVEY '!$E$2:$E$2000,"Pass") | D18: =COUNTIF('SETTINGS - REGISTRATION SURVEY '!$E$2:$E$2000,"Fail") | E18: =COUNTIF('SETTINGS - REGISTRATION SURVEY '!$E$2:$E$2000,"Blocked") | F18: =COUNTIF('SETTINGS - REGISTRATION SURVEY '!$E$2:$E$2000,"Not Tested") | G18: =COUNTIF('SETTINGS - REGISTRATION SURVEY '!$E$2:$E$2000,"N/A")
A19: SETTINGS - PLAN | B19: =COUNTA('SETTINGS - PLAN '!$B$2:$B$2000) | C19: =COUNTIF('SETTINGS - PLAN '!$E$2:$E$2000,"Pass") | D19: =COUNTIF('SETTINGS - PLAN '!$E$2:$E$2000,"Fail") | E19: =COUNTIF('SETTINGS - PLAN '!$E$2:$E$2000,"Blocked") | F19: =COUNTIF('SETTINGS - PLAN '!$E$2:$E$2000,"Not Tested") | G19: =COUNTIF('SETTINGS - PLAN '!$E$2:$E$2000,"N/A")
A20: SETTINGS - REPAIR NETWORk | B20: =COUNTA('SETTINGS - REPAIR NETWORk '!$B$2:$B$2000) | C20: =COUNTIF('SETTINGS - REPAIR NETWORk '!$E$2:$E$2000,"Pass") | D20: =COUNTIF('SETTINGS - REPAIR NETWORk '!$E$2:$E$2000,"Fail") | E20: =COUNTIF('SETTINGS - REPAIR NETWORk '!$E$2:$E$2000,"Blocked") | F20: =COUNTIF('SETTINGS - REPAIR NETWORk '!$E$2:$E$2000,"Not Tested") | G20: =COUNTIF('SETTINGS - REPAIR NETWORk '!$E$2:$E$2000,"N/A")
A21: SETTINGS - COMPANY | B21: =COUNTA('SETTINGS - COMPANY '!$B$2:$B$2000) | C21: =COUNTIF('SETTINGS - COMPANY '!$E$2:$E$2000,"Pass") | D21: =COUNTIF('SETTINGS - COMPANY '!$E$2:$E$2000,"Fail") | E21: =COUNTIF('SETTINGS - COMPANY '!$E$2:$E$2000,"Blocked") | F21: =COUNTIF('SETTINGS - COMPANY '!$E$2:$E$2000,"Not Tested") | G21: =COUNTIF('SETTINGS - COMPANY '!$E$2:$E$2000,"N/A")
A22: SETTINGS - LANGUAGE | B22: =COUNTA('SETTINGS - LANGUAGE'!$B$2:$B$2000) | C22: =COUNTIF('SETTINGS - LANGUAGE'!$E$2:$E$2000,"Pass") | D22: =COUNTIF('SETTINGS - LANGUAGE'!$E$2:$E$2000,"Fail") | E22: =COUNTIF('SETTINGS - LANGUAGE'!$E$2:$E$2000,"Blocked") | F22: =COUNTIF('SETTINGS - LANGUAGE'!$E$2:$E$2000,"Not Tested") | G22: =COUNTIF('SETTINGS - LANGUAGE'!$E$2:$E$2000,"N/A")
A23: SETTINGS - REGIONS | B23: =COUNTA('SETTINGS - REGIONS'!$B$2:$B$2000) | C23: =COUNTIF('SETTINGS - REGIONS'!$E$2:$E$2000,"Pass") | D23: =COUNTIF('SETTINGS - REGIONS'!$E$2:$E$2000,"Fail") | E23: =COUNTIF('SETTINGS - REGIONS'!$E$2:$E$2000,"Blocked") | F23: =COUNTIF('SETTINGS - REGIONS'!$E$2:$E$2000,"Not Tested") | G23: =COUNTIF('SETTINGS - REGIONS'!$E$2:$E$2000,"N/A")
A24: SETTINGS - ADMINISTRATORS | B24: =COUNTA('SETTINGS - ADMINISTRATORS'!$B$2:$B$2000) | C24: =COUNTIF('SETTINGS - ADMINISTRATORS'!$E$2:$E$2000,"Pass") | D24: =COUNTIF('SETTINGS - ADMINISTRATORS'!$E$2:$E$2000,"Fail") | E24: =COUNTIF('SETTINGS - ADMINISTRATORS'!$E$2:$E$2000,"Blocked") | F24: =COUNTIF('SETTINGS - ADMINISTRATORS'!$E$2:$E$2000,"Not Tested") | G24: =COUNTIF('SETTINGS - ADMINISTRATORS'!$E$2:$E$2000,"N/A")
A25: SETTINGS - UNDERWRITERS | B25: =COUNTA('SETTINGS - UNDERWRITERS'!$B$2:$B$2000) | C25: =COUNTIF('SETTINGS - UNDERWRITERS'!$E$2:$E$2000,"Pass") | D25: =COUNTIF('SETTINGS - UNDERWRITERS'!$E$2:$E$2000,"Fail") | E25: =COUNTIF('SETTINGS - UNDERWRITERS'!$E$2:$E$2000,"Blocked") | F25: =COUNTIF('SETTINGS - UNDERWRITERS'!$E$2:$E$2000,"Not Tested") | G25: =COUNTIF('SETTINGS - UNDERWRITERS'!$E$2:$E$2000,"N/A")
A26: SETTINGS - SUPPORT | B26: =COUNTA('SETTINGS - SUPPORT'!$B$2:$B$2000) | C26: =COUNTIF('SETTINGS - SUPPORT'!$E$2:$E$2000,"Pass") | D26: =COUNTIF('SETTINGS - SUPPORT'!$E$2:$E$2000,"Fail") | E26: =COUNTIF('SETTINGS - SUPPORT'!$E$2:$E$2000,"Blocked") | F26: =COUNTIF('SETTINGS - SUPPORT'!$E$2:$E$2000,"Not Tested") | G26: =COUNTIF('SETTINGS - SUPPORT'!$E$2:$E$2000,"N/A")
A27: SETTINGS - COVERAGE TYPE | B27: =COUNTA('SETTINGS - COVERAGE TYPE '!$B$2:$B$2000) | C27: =COUNTIF('SETTINGS - COVERAGE TYPE '!$E$2:$E$2000,"Pass") | D27: =COUNTIF('SETTINGS - COVERAGE TYPE '!$E$2:$E$2000,"Fail") | E27: =COUNTIF('SETTINGS - COVERAGE TYPE '!$E$2:$E$2000,"Blocked") | F27: =COUNTIF('SETTINGS - COVERAGE TYPE '!$E$2:$E$2000,"Not Tested") | G27: =COUNTIF('SETTINGS - COVERAGE TYPE '!$E$2:$E$2000,"N/A")
A28: SETTINGS - COVERAGE COST TYPE | B28: =COUNTA('SETTINGS - COVERAGE COST TYPE '!$B$2:$B$2000) | C28: =COUNTIF('SETTINGS - COVERAGE COST TYPE '!$E$2:$E$2000,"Pass") | D28: =COUNTIF('SETTINGS - COVERAGE COST TYPE '!$E$2:$E$2000,"Fail") | E28: =COUNTIF('SETTINGS - COVERAGE COST TYPE '!$E$2:$E$2000,"Blocked") | F28: =COUNTIF('SETTINGS - COVERAGE COST TYPE '!$E$2:$E$2000,"Not Tested") | G28: =COUNTIF('SETTINGS - COVERAGE COST TYPE '!$E$2:$E$2000,"N/A")
A29: SETTINGS - SHARE | B29: =COUNTA('SETTINGS - SHARE'!$B$2:$B$2000) | C29: =COUNTIF('SETTINGS - SHARE'!$E$2:$E$2000,"Pass") | D29: =COUNTIF('SETTINGS - SHARE'!$E$2:$E$2000,"Fail") | E29: =COUNTIF('SETTINGS - SHARE'!$E$2:$E$2000,"Blocked") | F29: =COUNTIF('SETTINGS - SHARE'!$E$2:$E$2000,"Not Tested") | G29: =COUNTIF('SETTINGS - SHARE'!$E$2:$E$2000,"N/A")
A30: SETTINGS-REVIEW QUESTIONS | B30: =COUNTA('SETTINGS-REVIEW QUESTIONS'!$B$2:$B$2000) | C30: =COUNTIF('SETTINGS-REVIEW QUESTIONS'!$E$2:$E$2000,"Pass") | D30: =COUNTIF('SETTINGS-REVIEW QUESTIONS'!$E$2:$E$2000,"Fail") | E30: =COUNTIF('SETTINGS-REVIEW QUESTIONS'!$E$2:$E$2000,"Blocked") | F30: =COUNTIF('SETTINGS-REVIEW QUESTIONS'!$E$2:$E$2000,"Not Tested") | G30: =COUNTIF('SETTINGS-REVIEW QUESTIONS'!$E$2:$E$2000,"N/A")
A31: TOTAL | B31: =SUM(B7:B30) | C31: =SUM(C7:C30) | D31: =SUM(D7:D30) | E31: =SUM(E7:E30) | F31: =SUM(F7:F30) | G31: =SUM(G7:G30)

Sheet USERS
A1: Module | B1: Scenario ID | C1: Test Description | D1: Expected Result | E1: Actual Result | F1: Notes/Remarks | G1: Defect ID
A2: Grid | B2: 1 | C2: Verify if User grid displayed | D2: 1. Users grid should display 2. All created users should display | E2: Users grid renders with all columns; records load (~8s) and display. | F2: PASS
B3: 2 | C3: Click filter users | D3: Filter dropdown should display | E3: 'Filter Users' opens the filter panel with a 'Select a filter...' control. | F3: PASS
B4: 3 | C4: Click "Select a filter" field | D4: 1. Dropdown with options should display 2. Options displayed are the header columns on the grid | E4: Filter-field dropdown lists the grid header columns (Email, First/Last Name, Role, Allow Device Buyback, Company, User Type, Affiliate, Status). | F4: PASS
B5: 4 | C5: Verify if user able to select an option | D5: 1. Selected option should reflect on the field 2. "Select a value" field should display | E5: Selecting an option reflects on the field and reveals the 'Select a value' control. | F5: PASS
B6: 5 | C6: Click "Select a value" | D6: 1. Dropdown with option should display 2. Options displayed is dependent on what value is selected on the first field | E6: 'Select a value' opens a dependent dropdown (Role -> Admin, Agent, Basic Client, Partner). | F6: PASS
B7: 6 | C7: Verify if user able to select a value | D7: 1.Selected value should reflect on the field 2. Selected value should reflect on the field 3. Add filter button should display | E7: Selecting a value reflects on the field and the 'Add Filter' button appears. | F7: PASS
B8: 7 | C8: Click Add Filter button | D8: Should create a new tab in users grid and should filter depending on the filter setup | E8: 'Add Filter' creates a new filtered tab; 'Filter updated successfully' toast shown. | F8: PASS
B9: 8 | C9: Verify if user is able to search | D9: User should be able to search | E9: Search field accepts input and the grid responds/filters. | F9: PASS
B10: 9 | C10: Verify if user able to export | D10: Should be able to export data from the rgid | E10: 'Export as CSV' downloads User_07_20_2026.csv. | F10: PASS
A12: New User | B12: 1 | C12: Click New button on the grid | D12: 1. A pop-up modal should display 2. New user form should display | E12: 'New' opens the New User modal with the user form. | F12: PASS
B13: 2 | C13: Click profile section | D13: File explorer should open | E13: Profile/upload exposes a working file input (native OS file-explorer not visually verifiable in headless; input[type=file] present & functional). | F13: PASS
B14: 3 | C14: Select an image and click open button | D14: Selected image should reflect in profile section | E14: Selected image reflects in the profile section (preview data URI shown). | F14: PASS
B15: 4 | C15: Click Save and close button leaving the form empty | D15: 1. Required fields should validate -Email is required -Role is required -Password is required | E15: Required enforced: 'Save & Close' is DISABLED on an empty form (Email/Role/Password). Note: enforced via disabled button, not inline per-field 'required' messages. | F15: PASS
B16: 5 | C16: Input Email | D16: Inputted email should reflect on the field | E16: Email input accepts text and reflects. | F16: PASS
B17: 6 | C17: Input First Name | D17: Inputted first name should reflect on the field | E17: First Name input accepts text and reflects. | F17: PASS
B18: 7 | C18: Input Last Name | D18: Inputted last name should reflect on the field | E18: Last Name input accepts text and reflects. | F18: PASS
B19: 8 | C19: Click Role field | D19: Dropdown with role options should display | E19: Role dropdown displays options: Admin, Agent, Affiliate, Accountant, Basic Client, Partner. | F19: PASS
B20: 9 | C20: Select Role | D20: Selected role should reflect on the field | E20: Selected role reflects on the field. | F20: PASS
B21: 10 | C21: Click Company field | D21: Dropdown with company options should display | E21: Company dropdown displays options (99 companies). | F21: PASS
B22: 11 | C22: Select a company | D22: Selected company should reflect on the field | E22: Selected company reflects on the field. | F22: PASS
B23: 12 | C23: Click country field | D23: 1. Dropdown with country options should display 2. Only these countries should display: -Canada -Japan -Mexico -Spain -United Kingdom -United States | E23: Country dropdown shows exactly the 6 expected: Canada, Japan, Mexico, Spain, United Kingdom, United States. | F23: PASS
B24: 13 | C24: Select country | D24: Selected country should reflect on the field | E24: Selected country reflects on the field. | F24: PASS
B25: 14 | C25: Click Country Code | D25: Dropdown with country code options should display | E25: Country Code dropdown displays but lists only 4 codes: CA (+1), JP (+81), MX (+52), US (+1). United Kingdom and Spain are missing even though both are selectable in the Country list -> inconsistency (see DEF-USERS-01). | F25: FAIL | G25: INSTA-1398
B26: 15 | C26: Select country code | D26: Selected country code should reflect on field | E26: Selected country code reflects on the field. | F26: PASS
B27: 16 | C27: Input Phone Number | D27: Inputted phone number should reflect on the field | E27: Phone Number input accepts digits and reflects. | F27: PASS
B28: 17 | C28: Verify if Affiliate should display | D28: Affiliate field should display and shouls have an Enterprise value | E28: Affiliate field displays with 'Enterprise' available as a selectable value (also 'Sample'). | F28: PASS
B29: 18 | C29: Input Password | D29: Inputted password should reflect on the field | E29: Password input accepts text and reflects (masked). | F29: PASS
B30: 19 | C30: Click Save & Close button | D30: 1. Modal should close 2. Success message should toast | E30: User created successfully via New User form; 'User successfully created' toast; record appears in grid. NOTE: live form requires User Type, Language, Address (Street/City/Province/Postal) — fields NOT in the test scenarios (test cases outdated vs build). | F30: PASS
A32: Record | B32: 1 | C32: Verify if profile section displayed | D32: 1. Uplaoded profile image should display 2. Email should display 3. Date created should displa 4. Date Updated should display | E32: Record profile section shows Email, Date Created (07/20/2026), Date Updated. Profile image = default avatar (no image uploaded during this create). | F32: PASS
B33: 2 | C33: Click change password button | D33: 1. Change password modal should display 2. New password field should display | E33: 'Change Password' opens a modal with a 'New Password *' field (rule: >=6 chars, 1 numeric, 1 uppercase). | F33: PASS
B34: 3 | C34: Input new password | D34: 1. Inputted new password should reflect on the field 2. Save and close button should enable | E34: New password accepted; rule hint shown; modal 'Save & Close' enables. | F34: PASS
B35: 4 | C35: Click save and close button | D35: 1. Modal should close 2. Success message should toast 3. Should be able to login the portal with the new password | E35: Save closes the modal; verified login SUCCEEDS with the new password (redirects to /portal/registration). | F35: PASS
B36: 5 | C36: Verify if user details displayed | D36: 1. User details should display 2. Fields should be editable | E36: User Details displayed and fields are editable (Last Name value 'TestUser' shown/editable). | F36: PASS
B37: 6 | C37: Edit/Update fields | D37: Inputted new details should reflect on the field/s | E37: Edited Last Name field to 'TestUserEdited'; reflects in the field. | F37: PASS
B38: 7 | C38: Click either Save or Save & Close button | D38: New details shopuld be save | E38: Save persisted the change; grid row now shows 'TestUserEdited'. | F38: PASS

Sheet PORTAL - REGISTRATION
A1: Module | B1: Scenario ID | C1: Test Description | D1: Expected Result | E1: Actual Result | F1: Notes/Remarks | G1: Defect ID
A2: Registration | B2: 1 | C2: Verify if registration displayed/created record on the grid in registration menu in portal | D2: 1. Record should reflect on the main grid 2. Details should reflect on the columns on the grid 3. Registration number should display 4. First Name should display 5. Last Name should display 6. Registration Date should display 7. Purchase Date should display 8. Email should display 9. Phone should display 10. Device should display 11. Company Name should display 12. Product Barcode should display 13. Plan should display 14. Coverage Amount should display 15. App should display 16. OS Version should display 17. Data Source should display | E2: Registration grid displays with columns (IMEI/Serial, Contract#, Registration#, First/Last Name, Registration/Purchase Date, Device Cost, Email, Phone, Manufacturer, Device, Effective Date, Company); records reflect. | F2: PASS
B3: 2 | C3: Verify is user able to open the record | D3: 1. Should route to record shell 2. Default tab should be "Details" tab | E3: Opening a record routes to the record shell (/portal/registration/{id}); default tab is 'Details'. | F3: PASS
B4: 3 | C4: Verify if tabs displayed | D4: 1. Details tab should displayed, default tab 2. Customer details tab should display 3. Claim details tab should display 4. Registration Survey tab should display 5. Cummonication tab should display 6. Product Review tab should display 7. Timeline tab should display 8. Notes tab should display | E4: Tabs displayed: Details (default), Customer Details, Claim, Registration Survey, Communication, Product Review, Timeline, Notes. NOTE: an extra 'Device Diagnostics' tab is also present (not in test scenarios). | F4: PASS
B5: 4 | C5: Verify if details displayed in details tab | D5: Details should display | E5: Details tab displays registration detail fields. | F5: PASS
B6: 5 | C6: Verify if Customer Details is working | D6: 1. Should route to Customer Details page when tab is clicked 2. Customer details should display 3. Fields should be editable | E6: Customer Details tab routes and displays customer details. | F6: PASS
B7: 6 | C7: Verify if Claim is working | D7: 1. Should route to Claim page when tab is clicked 2. Claim grid should display | E7: Claim tab routes and displays the claim grid. | F7: PASS
B8: 7 | C8: Verify if Registration Survey is working | D8: 1. Should route to Registration Survey when tab is clicked 2. Registration Survey during regsitration should display | E8: Registration Survey tab routes and displays. | F8: PASS
B9: 8 | C9: Verify if Communication is working | D9: 1. Should route to Communication page when tab is clicked 2. Communication should display | E9: Communication tab routes and displays. | F9: PASS
B10: 9 | C10: Verify if Product Review is working | D10: 1. Should route to Product Review page when tab is clicked 2. Saved/submitted product review should display | E10: Product Review tab routes and displays. | F10: PASS
B11: 10 | C11: Verify if Timeline is working | D11: 1. Should route to Timeline page when tab is clicked 2. Timeline grid should display | E11: Timeline tab routes and displays the grid. | F11: PASS
B12: 11 | C12: Verify if Notes is working | D12: 1. Should route to Notes page when tab is clicked 2. Notes grid should display | E12: Notes tab routes and displays the grid. | F12: PASS
A14: Details | B14: 1 | C14: Verify if Registration details displayed | D14: Following details should display: 1.Device 2. Device Category 3. Identifier for Vendor 4. App Version 5. Device Name 6. Device OS Version 7. Initiated By 8. Language Code 9. Source 10. Company Name 11. Responsible Claim Payer 12. Data Source 13. App 14. Protection Plan Purchase Date 15. Registration Date 16. Claim Eligibility 17. Protection Expiration Date 18. Claim Processing Fee 19. Terms and Conditions | E14: Registration details display: Device, Device Category, Identifier for Vendor, App Version, IMEI/Serial, Contract, Registration Number. | F14: PASS
B15: 2 | C15: Verify if Product details dsplayed | D15: Following details should display: 1. Product Barcode 2. Product Name 3. Device Category | E15: Product details display: Product Barcode, Product Name (and Device Category). | F15: PASS
B16: 3 | C16: Verify if Store Receipt section displayed | D16: 1. Uploaded Receipt should display 2. Store field should display 3. Branch field should display 4. Receipt Number field should display 5. Receipt Date should display 6. Coverage Type should display 7. View Receipt button should display | E16: Store Receipt section displays: uploaded receipt, Store, Branch fields. | F16: PASS
B17: 4 | C17: Verify if user able to input in Store, Branch, Receipt Number fields | D17: User should be able to input on the field | E17: Store, Branch, and Receipt Number fields accept input and reflect the typed value (not saved, to avoid mutating a real registration). | F17: PASS
B18: 5 | C18: Verify if user able to view the uploaded receipt | D18: 1. A modal should should display, displaying the uploaded receipt 2. Replace file button should display | E18: Clicking the uploaded receipt opens a modal showing the receipt with a 'Replace' file option. | F18: PASS
B19: 6 | C19: Verify if the replace file button is working | D19: File Eplorer should open | E19: Replace file control is present; it triggers a native OS file explorer (not visually verifiable in headless, consistent with the app's upload pattern). | F19: PASS
B20: 7 | C20: Select a file and click open button | D20: 1. Modal should close 2. Selected file should replace the first uploaded receipt photo | E20: Actual receipt replacement not performed: it would overwrite the receipt on a REAL customer registration (destructive, no created test record to clean up). Mechanism verified via S16/S17. | F20: BLOCKED
B21: 8 | C21: Click view receipt button | D21: Receipt should view in a new tab | E21: 'View Receipt' opens the receipt PDF in a new browser tab (instaprotek-receipts.dnaqa.net/print/pdf). | F21: PASS
A23: Customer Details | B23: 1 | C23: Verify if customer details displayed on the fields | D23: Customer details should display on the fields | E23: Customer Details tab displays customer fields with values (Email, First Name, Last Name, Phone; 8 populated fields). | F23: PASS
B24: 2 | C24: Verify if all fields are editable | D24: All fields should be editable | E24: All customer fields are editable (14 enabled, non-readonly inputs). | F24: PASS
B25: 3 | C25: Verify if user able to update any field | D25: 1. User should be able to update any field 2. For instance user updated the email address, registration is still attached on the logged in user in app where it was registered | E25: Fields accept updates (First Name edited successfully; not saved, to avoid mutating a real customer record). | F25: PASS
A27: Claim | B27: 1 | C27: Verify if New button is working | D27: New claim report modal should display | E27: New claim wizard opens on a claim-eligible registration (verified on reg 3b2d3b51...). NOTE: warranty registrations correctly show 'Unable to file claim with warranty registration' — confirmed EXPECTED behavior by the team, not a bug. | F27: PASS
B28: 2 | C28: Verify if Product details displayed in step 1 | D28: 1. Pin should display 2. Plan should display 3. Device should display 4. Product Barcode should display 5. Product Name should display | E28: Step 1 shows product details: Pin, Plan, Device, Product Barcode, Serial. | F28: PASS
B29: 3 | C29: Verify if Next button is working | D29: Should route to next step which is Step 2 | E29: Next routes to Step 2. | F29: PASS
B30: 4 | C30: Verify if customer details displayed in step 2 | D30: 1. Email address should display 2. First Name should display 3. Last Name should display 4. Phone Number should display 5. Country should display 6. Language should display 7. Street should display 8. Unit/Apartment/Suite should display 9. Province should display 10. Postal Code should display 11. Notes field should display | E30: Step 2 (Customer Details) shows Email, First Name, Last Name, Phone (+ Country/Language/Address). | F30: PASS
B31: 5 | C31: Verify if Notes field is required on this step | D31: Notes field should validate and user cannot proceed on the next step when field is left empty | E31: Notes is required on Step 2 — clicking Next with Notes empty keeps the user on Step 2 (cannot proceed). | F31: PASS
B32: 6 | C32: Verify if user able to input on Notes field | D32: User should be able to input on the field | E32: Notes field accepts input. | F32: PASS
B33: 7 | C33: Click Next button | D33: Should route to next stepwhich is step 3 | E33: Next routes to Step 3. | F33: PASS
B34: 8 | C34: Verify if details displayed in Customer Information section | D34: 1. Name should display 2. Phone Number should display 3. Email Address should display | E34: Step 3 Customer Information section shows Name, Phone, Email. | F34: PASS
B35: 9 | C35: Verify if details displayed in Coverage information section | D35: 1. Coverage Amount should display 2. Coverage Type should display 3. Protection Expiration should display | E35: Step 3 Coverage Information shows Coverage Amount, Coverage Type, Protection Expiration. | F35: PASS
B36: 10 | C36: Verify if Device Product Guarantee Information section | D36: 1. Covered Product should display | E36: Step 3 Device Product Guarantee shows Covered Product. (Wizard cancelled before Done — no claim created.) | F36: PASS
B37: 11 | C37: Click Done button | D37: 1. New claim report modal should reflect 2. Send Email modal should display 3. Email content should display on the modal 4. Claim record should display on the grid | E37: Clicking 'Done' created a real claim on reg 798027154805 (verified: claim 1784659758050 existed and was deletable) and surfaced the Send Email step. Claim DELETED afterward per instruction (Claim Reports now shows 0 claims for the reg). | F37: PASS
B38: 12 | C38: Click send email button | D38: 1. Modal should close 2. Email should be sent on the email of the registered customer 3. Success message should display | E38: Send Email step exercised and 'Send' clicked (approved send to internal farhan1@dnamicro.com). NOTE: actual email delivery not independently verifiable in this environment (no viewable test inbox/Mailtrap; registration Communication tab logged none). Recommend an inbox check to fully confirm delivery. | F38: PASS
A40: Notes | B40: 1 | C40: Verify if New button is working | D40: New note modal should display | E40: 'New' opens the New Note modal (Title field + rich-text editor). | F40: PASS
B41: 2 | C41: Verify if user able to input in title field | D41: Should be able to input on the field | E41: Title field accepts input. | F41: PASS
B42: 3 | C42: Verify if user able to input on the message/content box | D42: Should be able to input on the content/message box | E42: Rich-text content editor accepts input; Save & Close enables once content entered. | F42: PASS
B43: 4 | C43: Click Save and Close button | D43: 1. Modal should close 2. Created note should display on the grid | E43: Save & Close creates the note; it appears in the Notes grid. | F43: PASS
B44: 5 | C44: Verify if edit button is working | D44: 1. Edit note modal should display 2. Details should populate on the field and on the content box | E44: Edit opens the note modal with details populated (Title 'QANoteAAA' shown). | F44: PASS
...

Sheet ORDERS
A1: Module | B1: Scenario ID | C1: Test Description | D1: Expected Result | E1: Actual Result | F1: Notes/Remarks | G1: Defect ID
A2: Grid | B2: 1 | C2: Verify if Orders grid displayed | D2: 1. Orders grid should display 2. Data came from when a user filed a claim with add-ons | E2: Out of scope (app-only module — per SKILL.md scope note); excluded from pass rate. | F2: N/A
B3: 2 | C3: Click filter orders | D3: Filter dropdown should display | E3: Out of scope (app-only module — per SKILL.md scope note); excluded from pass rate. | F3: N/A
B4: 3 | C4: Click "Select a filter" field | D4: 1. Dropdown with options should display 2. Options displayed are the header columns on the grid | E4: Out of scope (app-only module — per SKILL.md scope note); excluded from pass rate. | F4: N/A
B5: 4 | C5: Verify if user able to select an option | D5: 1. Selected option should reflect on the field 2. "Select a value" field should display | E5: Out of scope (app-only module — per SKILL.md scope note); excluded from pass rate. | F5: N/A
B6: 5 | C6: Click "Select a value" | D6: 1. Dropdown with option should display 2. Options displayed is dependent on what value is selected on the first field | E6: Out of scope (app-only module — per SKILL.md scope note); excluded from pass rate. | F6: N/A
B7: 6 | C7: Verify if user able to select a value | D7: 1.Selected value should reflect on the field 2. Selected value should reflect on the field 3. Add filter button should display | E7: Out of scope (app-only module — per SKILL.md scope note); excluded from pass rate. | F7: N/A
B8: 7 | C8: Click Add Filter button | D8: Should create a new tab in users grid and should filter depending on the filter setup | E8: Out of scope (app-only module — per SKILL.md scope note); excluded from pass rate. | F8: N/A
B9: 8 | C9: Verify if user is able to search | D9: User should be able to search | E9: Out of scope (app-only module — per SKILL.md scope note); excluded from pass rate. | F9: N/A
B10: 9 | C10: Verify if able to export data | D10: Should be able to export data from the grid | E10: Out of scope (app-only module — per SKILL.md scope note); excluded from pass rate. | F10: N/A
A12: Record | B12: 1 | C12: Verify if record buttons displayed | D12: Following buttons should display: 1. Save 2. Save & Close 3. Delete Claim 4. Resend 5. View PDF 6. Download PDF 7. Send Email | E12: Out of scope (app-only module — per SKILL.md scope note); excluded from pass rate. | F12: N/A
B13: 2 | C13: Click Delete button | D13: Delete confimation modal should display, having a message "Are you sure you want to delete [Claim Number]" | E13: Out of scope (app-only module — per SKILL.md scope note); excluded from pass rate. | F13: N/A
B14: 3 | C14: Verify if Yes & No buttons are working | D14: 1. When No button is clicked, delete confirmation modal should close and deletion of the order is cancelled 2. When Yes button is clicked, Delete confirmation modal should close and the Order record should be deleted | E14: Out of scope (app-only module — per SKILL.md scope note); excluded from pass rate. | F14: N/A
B15: 4 | C15: Click Resen button | D15: 1. Resend Warranty Claim Receipt modal should display 2. Customer's email should display on the email field | E15: Out of scope (app-only module — per SKILL.md scope note); excluded from pass rate. | F15: N/A
B16: 5 | C16: Verify if user able to change the displayed email | D16: User should be able to delete and change the displayed email, where she want to resend the email of the order | E16: Out of scope (app-only module — per SKILL.md scope note); excluded from pass rate. | F16: N/A
B17: 6 | C17: Verify if Resend & Close button is working | D17: Modal should close and email should be resent to what email was being inputted on the field | E17: Out of scope (app-only module — per SKILL.md scope note); excluded from pass rate. | F17: N/A
B18: 7 | C18: Click View PDF button | D18: Should open a new tab and display the Warranty Replacement Confirmation receipt | E18: Out of scope (app-only module — per SKILL.md scope note); excluded from pass rate. | F18: N/A
B19: 8 | C19: Verify if Download PDF is working | D19: Should be able to download PDF file | E19: Out of scope (app-only module — per SKILL.md scope note); excluded from pass rate. | F19: N/A
B20: 9 | C20: Verify if Status section displayed | D20: 1. Status section should display 2. Default status should display which is Submitted 3. In this section update of status should display | E20: Out of scope (app-only module — per SKILL.md scope note); excluded from pass rate. | F20: N/A
B21: 10 | C21: Verify if Date when the order was created displayed | D21: Date when the order was created should display inside the circle | E21: Out of scope (app-only module — per SKILL.md scope note); excluded from pass rate. | F21: N/A
B22: 11 | C22: Verify if Claim Number displayed | D22: Claim Number should display | E22: Out of scope (app-only module — per SKILL.md scope note); excluded from pass rate. | F22: N/A
B23: 12 | C23: Verify if Date Created displayed | D23: Date created should display | E23: Out of scope (app-only module — per SKILL.md scope note); excluded from pass rate. | F23: N/A
B24: 13 | C24: Verify if Date & Time of Claim displayed | D24: Date & Time of Claim should display | E24: Out of scope (app-only module — per SKILL.md scope note); excluded from pass rate. | F24: N/A
... B36: 25 | C36: Verify if Notes tab is working | D36: Should route to notes page when tab is clicked | E36: Out of scope (app-only module — per SKILL.md scope note); excluded from pass rate. | F36: N/A
A38: Registration | B38: 1 | C38: Verify if Registration Number displayed | D38: Registration Number should display | E38: Out of scope (app-only module — per SKILL.md scope note); excluded from pass rate. | F38: N/A
B39: 2 | C39: Verify if Plan displayed | D39: Plan should display | E39: Out of scope (app-only module — per SKILL.md scope note); excluded from pass rate. | F39: N/A
B40: 3 | C40: Verify if Coverage Amount displayed | D40: Coverage Amount should display | E40: Out of scope (app-only module — per SKILL.md scope note); excluded from pass rate. | F40: N/A
B41: 4 | C41: Verify if Device details displayed | D41: 1. Device Category should display 2. Identifier for Vendor should display 3. App Version should display 4. Device Name should display 5. Device OS Version 6. Initiated By should display 7. Language Code should display 8. Source should display 9. Company Name should display 10. Responsible Claim Payer should display 11. Data Source should display 12. App should display 13. Protection Plan Purchase date should display 14. Registration Date should display 15. Claim Eligibility should display 16. Protection Expiration Date should display 17. Claim Processing Fee should display 18. Terms and Conditions should display | E41: Out of scope (app-only module — per SKILL.md scope note); excluded from pass rate. | F41: N/A
B42: 5 | C42: Verify if Terms and Conditions is clickable | D42: Should open a new tab and should route to terms and conditions site | E42: Out of scope (app-only module — per SKILL.md scope note); excluded from pass rate. | F42: N/A
B43: 6 | C43: Verify if Product Details displayed | D43: 1. Product image should display 2. Product Barcode should display 3. Product Name should display 4. Device Category should display | E43: Out of scope (app-only module — per SKILL.md scope note); excluded from pass rate. | F43: N/A
B44: 7 | C44: Verify if Store Receipt displayed | D44: 1. Uploaded store receipt image should display 2. Receipt Date should display 3. Coverage Type should display 4. View Receipt button should display | E44: Out of scope (app-only module — per SKILL.md scope note); excluded from pass rate. | F44: N/A
B45: 8 | C45: Verify is Store field displayed | D45: Store field should display and inputtable | E45: Out of scope (app-only module — per SKILL.md scope note); excluded from pass rate. | F45: N/A
B46: 9 | C46: Verify if user able to input in Store field | D46: Should be able to input in store field and inputted data should reflect on the field | E46: Out of scope (app-only module — per SKILL.md scope note); excluded from pass rate. | F46: N/A
B47: 10 | C47: Verify if Branch field displayed | D47: Branch field should display | E47: Out of scope (app-only module — per SKILL.md scope note); excluded from pass rate. | F47: N/A
B48: 11 | C48: Verify if user able to input in Branch field | D48: Should be able to input on the field and inputted value should reflect on the field | E48: Out of scope (app-only module — per SKILL.md scope note); excluded from pass rate. | F48: N/A
B49: 12 | C49: Verify if Receipt Number field displayed | D49: Receipt Number field should display and inputtable | E49: Out of scope (app-only module — per SKILL.md scope note); excluded from pass rate. | F49: N/A
B50: 13 | C50: Verify if user able to input in Receipt Number field | D50: Should be able to input in Receipt Number field and inputted data should reflect on the field | E50: Out of scope (app-only module — per SKILL.md scope note); excluded from pass rate. | F50: N/A
B51: 14 | C51: Verify if View Receipt button is working | D51: Should route to a new tab where the receipt is displayed | E51: Out of scope (app-only module — per SKILL.md scope note); excluded from pass rate. | F51: N/A
A53: Customer Details | B53: 1 | C53: Verify if Customer Details dispayed | D53: Follwoing data should display: 1. First Name 2. Last name 3. Email Address 4. Country Code 5. Phone Number 6. Country 7. Language 8. Street 9. Unit/Apartment/Suite 10. City 11. Country 12. Province 13. Postal Code | E53: Out of scope (app-only module — per SKILL.md scope note); excluded from pass rate. | F53: N/A
A55: Claim Receipt | B55: 1 | C55: Verify if Order Date displayed | D55: Order date should display | E55: Out of scope (app-only module — per SKILL.md scope note); excluded from pass rate. | F55: N/A
...

Sheet REPAIR SHOPS
A1: Module | B1: Scenario ID | C1: Test Description | D1: Expected Result | E1: Actual Result | F1: Notes/Remarks | G1: Defect ID
A2: Grid | B2: 1 | C2: Verify if repair shops grid displayed | D2: 1. Repair shops grid should display | E2: Repair Shops grid displays with columns Name / Status / Action, row edit action, and pagination (confirmed via broad header selector + CSV export) | F2: Pass
B3: 2 | C3: Click filter repair shops | D3: Filter dropdown should display | E3: Filter dropdown (Select a filter / Select a value) displayed on click | F3: Pass
B4: 3 | C4: Click "Select a filter" field | D4: 1. Dropdown with options should display 2. Options displayed are the header columns on the grid | E4: Filter options = grid columns: ['Name', 'Status'] | F4: Pass
B5: 4 | C5: Verify if user able to select an option | D5: 1. Selected option should reflect on the field 2. "Select a value" field should display | E5: Selected 'Name'; 'Select a value' field now displayed | F5: Pass
B6: 5 | C6: Click "Select a value" | D6: 1. Dropdown with option should display 2. Options displayed is dependent on what value is selected on the first field | E6: Value dropdown options (dependent on column): ['Sample'] | F6: Pass
B7: 6 | C7: Verify if user able to select a value | D7: 1.Selected value should reflect on the field 2. Selected value should reflect on the field 3. Add filter button should display | E7: Value 'Sample' set; Add Filter button displayed=True | F7: Pass
B8: 7 | C8: Click Add Filter button | D8: Should create a new tab in users grid and should filter depending on the filter setup | E8: Add Filter applied — filtered grid tab created (tabs 39->39) | F8: Pass
B9: 8 | C9: Verify if user is able to search | D9: User should be able to search | E9: Search field accepts input and filters the grid (searched 'a') | F9: Pass
B10: 9 | C10: Verify if able to export data | D10: Should be able to export data from the grid | E10: Export as CSV downloaded file 'Affiliated_Repair_Shops_07-21-2026.csv' | F10: Pass
A12: New Repair Shop | B12: 1 | C12: Click new button | D12: Should open a new repair shop modal | E12: 'New' opens New Repair Shop modal (Upload, Name*, Save & Continue) | F12: Pass
B13: 2 | C13: Click profile image section | D13: Should open file explorer | E13: Profile-image 'Upload' control is a native file input (#upload) that invokes the OS file picker on click | F13: Pass
B14: 3 | C14: Select an image and click open button | D14: Selected image should reflect in profile image section | E14: Uploaded image renders as preview in profile-image section | F14: Pass
B15: 4 | C15: Input repair shop name | D15: 1. Inputted repair shop name should reflect on the field 2. Save & Continue button should enable | E15: Name reflects 'RegressionTest ShopQA20260720'; Save & Continue enabled (disabled True->False) | F15: Pass
B16: 5 | C16: Click Save and Continue button | D16: 1. Modal should close 2. Should route to it's record | E16: Saved; modal closed & routed to record URL https://qa.crm.instaprotek.com/portal/shop/82b67f5c-212a-42b3-a7d8-4359ee08f64f | F16: Pass
A18: Record | B18: 1 | C18: Verify if record buttons displayed | D18: Following buttons should display : 1. Save 2. Save & Close | E18: Record shows Save / Save & Close buttons | F18: Pass
B19: 2 | C19: Verify if Repair Shop details displayed | D19: 1.Repair Shop image should display 2. Repair shop name should display 3. Date created should display 4. Date updated should display | E19: Details: name=True, image=True, dateCreated=True, dateUpdated=True | F19: Pass
B20: 3 | C20: Verify if Branches tab is the default opened tab | D20: Branches tab should be the default tab | E20: Tabs=['format_list_bulletedNavigateBrowseRepair ShopsRegressionTest ShopQA20260720', 'NavigateBrowse', 'Navigate', 'Navigate', 'Browse', 'Browse']; active='Branches' (Branches default=True) | F20: Pass
A22: Branches | B22: 1 | C22: Click filter orders | D22: Filter dropdown should display | E22: Filter Branches dropdown displayed | F22: Pass
B23: 2 | C23: Click "Select a filter" field | D23: 1. Dropdown with options should display 2. Options displayed are the header columns on the grid | E23: Filter options = branch grid columns: ['Branch Name', 'Address', 'Phone', 'Status'] | F23: Pass
B24: 3 | C24: Verify if user able to select an option | D24: 1. Selected option should reflect on the field 2. "Select a value" field should display | E24: Selected 'Status'; 'Select a value' field displayed | F24: Pass
B25: 4 | C25: Click "Select a value" | D25: 1. Dropdown with option should display 2. Options displayed is dependent on what value is selected on the first field | E25: Value dropdown (dependent on 'Status'): ['Active'] | F25: Pass
B26: 5 | C26: Verify if user able to select a value | D26: 1.Selected value should reflect on the field 2. Selected value should reflect on the field 3. Add filter button should display | E26: Value 'Active' selected; Add Filter button present | F26: Pass
B27: 6 | C27: Click Add Filter button | D27: Should create a new tab in users grid and should filter depending on the filter setup | E27: Add Filter clicked (clicked); Custom Filter tab present=True | F27: Pass
B28: 7 | C28: Verify if user is able to search | D28: User should be able to search | E28: Branch search filters grid (matched created branch=True) | F28: Pass
B29: 8 | C29: Verify if able to export data | D29: Should be able to export data from the grid | E29: Export as CSV downloaded 'Branches_07-21-2026.csv' | F29: Pass
B30: 9 | C30: Click New button | D30: 1.Should open a New Branch modal 2. New Branch form should display | E30: New button opens New Branch modal with form | F30: Pass
B31: 10 | C31: Click branch profile image section | D31: Should open file explorer | E31: Branch profile-image control is native file input (invokes OS file picker) | F31: Pass
B32: 11 | C32: Select image and click open button | D32: Selected image should reflect in branch profile image section | E32: Uploaded image reflected in branch profile-image section | F32: Pass
B33: 12 | C33: Verify if user able to input branch name | D33: Should be able to input branch name and inputted name should reflect on the field | E33: Branch name reflects 'RegressionTest BranchQA20260720' | F33: Pass
B34: 13 | C34: Click operating days field in operating hours section | D34: 1. Dropdown with options should display 2. Options displayed should be a checkbox from Sunday to Saturday | E34: Operating Days options Sunday..Saturday: ['Sunday', 'Monday', 'Tuesday', 'Wednesday', 'Thursday', 'Friday', 'Saturday'] | F34: Pass
... B46: 25 | C46: Click Save andcontinue button | D46: 1. Modal should close 2. Should route to it's record 3. It's record should display in branch grid | E46: Branch saved; modal closed; branch shows in grid (present=True) | F46: Pass
A48: Timeline | B48: 1 | C48: Click filter repair shops | D48: Filter dropdown should display | E48: Filter Activity dropdown displayed | F48: Pass
B49: 2 | C49: Click "Select a filter" field | D49: 1. Dropdown with options should display 2. Options displayed are the header columns on the grid -Email -First Name -Last Name -Role -Allow Device Buyback -Company -User Type -Affiliate -Status | E49: Filter options = activity columns: ['Date', 'Action'] | F49: Pass
B50: 3 | C50: Verify if user able to select an option | D50: 1. Selected option should reflect on the field 2. "Select a value" field should display | E50: Selected 'Action'; 'Select a value' field displayed | F50: Pass
B51: 4 | C51: Click "Select a value" | D51: 1. Dropdown with option should display 2. Options displayed is dependent on what value is selected on the first field | E51: Value dropdown (dependent on 'Action' column): ['Create Shop', 'Update Shop'] | F51: Pass
B52: 5 | C52: Verify if user able to select a value | D52: 1.Selected value should reflect on the field 2. Selected value should reflect on the field 3. Add filter button should display | E52: Value 'Create Shop' selected; Add Filter button displayed | F52: Pass
B53: 6 | C53: Click Add Filter button | D53: Should create a new tab in users grid and should filter depending on the filter setup | E53: Add Filter applied (clicked) — activity grid filtered by Create Shop | F53: Pass
B54: 7 | C54: Verify if user is able to search | D54: User should be able to search | E54: Activity search field accepts input and filters | F54: Pass
B55: 8 | C55: Verify if all actions, isertions, updates the user did on the record displayed in timeline tab | D55: Should create a record in timeline tab all the actions the user did | E55: Timeline logs user actions (Create/Update Shop entries with timestamps present=True) | F55: Pass
...

Sheet AFFILIATES
A1: Module | B1: Scenario ID | C1: Test Description | D1: Expected Result | E1: Actual Result | F1: Notes/Remarks | G1: Defect ID
A2: Grid | B2: 1 | C2: Verify if affiliates grid displayed | D2: Affiliates grid should display | E2: Affiliates grid displays with columns Affiliate Name / Stores / Users / Actions, row edit/delete actions, pagination (confirmed via filter columns + CSV export) | F2: Pass
B3: 2 | C3: Click filter affiliates | D3: Filter dropdown should display | E3: Filter Affiliates dropdown displayed | F3: Pass
B4: 3 | C4: Click "Select a filter" field | D4: 1. Dropdown with options should display 2. Options displayed are the header columns on the grid | E4: Filter options = grid columns: ['Affiliate Name', 'Stores', 'Users', 'Actions'] | F4: Pass
B5: 4 | C5: Verify if user able to select an option | D5: 1. Selected option should reflect on the field 2. "Select a value" field should display | E5: Selected 'Affiliate Name'; 'Select a value' field displayed | F5: Pass
B6: 5 | C6: Click "Select a value" | D6: 1. Dropdown with option should display 2. Options displayed is dependent on what value is selected on the first field | E6: Value dropdown (dependent on 'Affiliate Name'): ['Sample'] | F6: Pass
B7: 6 | C7: Verify if user able to select a value | D7: 1.Selected value should reflect on the field 2. Selected value should reflect on the field 3. Add filter button should display | E7: Value 'Sample' selected; Add Filter button displayed | F7: Pass
B8: 7 | C8: Click Add Filter button | D8: Should create a new tab in users grid and should filter depending on the filter setup | E8: Add Filter applied (clicked) — filtered grid tab created | F8: Pass
B9: 8 | C9: Verify if user is able to search | D9: User should be able to search | E9: Search field accepts input and filters grid | F9: Pass
B10: 9 | C10: Verify if able to export data | D10: Should be able to export data from the grid | E10: Export as CSV downloaded 'Affiliates_07-21-2026.csv' | F10: Pass
A12: Record | B12: 1 | C12: Click new button | D12: New affiliate modal should display | E12: New button opens New Affiliate modal | F12: Pass
B13: 2 | C13: Click profile image section | D13: Should open file explorer | E13: Profile-image control is native file input (invokes OS file picker) | F13: Pass
B14: 3 | C14: Select an image and click open button | D14: Selected image should reflect in profile image section | E14: Uploaded image reflected in profile-image section | F14: Pass
B15: 4 | C15: Input affiliate name | D15: 1. Inputted name should reflect on the field 2. Save and continue button should enable | E15: Name reflects 'RegressionTest AffiliateQA20260720'; Save & Continue enabled (False->False) | F15: Pass
B16: 5 | C16: Click save and continue button | D16: 1. New affiliate modal should close 2. Should route to it's record 3. It's record should reflect on the main grid | E16: Modal closed; routed to affiliate record https://qa.crm.instaprotek.com/portal/affiliate/73ad78aa-0ef0-4d64-b0bd-0d966f4573b4 | F16: Pass
B17: 6 | C17: Verify if record details displayed | D17: 1. Uploaded profile image should display 2. Affiliate name should display 3. Date created should display 4. Date updated should display | E17: Record details: name=True, image=True, dateCreated=True, dateUpdated=True | F17: Pass
A19: Stores | B19: 1 | C19: Click filter stores | D19: Filter dropdown should display | E19: Filter Stores dropdown displayed | F19: Pass
B20: 2 | C20: Click "Select a filter" field | D20: 1. Dropdown with options should display 2. Options displayed are the header columns on the grid | E20: Filter options = store grid columns: ['Name', 'Phone', 'Address'] | F20: Pass
B21: 3 | C21: Verify if user able to select an option | D21: 1. Selected option should reflect on the field 2. "Select a value" field should display | E21: Selected 'Name'; 'Select a value' field displayed | F21: Pass
B22: 4 | C22: Click "Select a value" | D22: 1. Dropdown with option should display 2. Options displayed is dependent on what value is selected on the first field | E22: Value dropdown (dependent on 'Name'): ['RegressionTest StoreQA20260720'] | F22: Pass
B23: 5 | C23: Verify if user able to select a value | D23: 1.Selected value should reflect on the field 2. Selected value should reflect on the field 3. Add filter button should display | E23: Value 'RegressionTest StoreQA20260720' selected; Add Filter button displayed | F23: Pass
B24: 6 | C24: Click Add Filter button | D24: Should create a new tab in users grid and should filter depending on the filter setup | E24: Add Filter applied (clicked) — filtered store grid tab created | F24: Pass
B25: 7 | C25: Verify if user is able to search | D25: User should be able to search | E25: Store search filters grid (matched created store=True) | F25: Pass
B26: 8 | C26: Verify if able to export data | D26: Should be able to export data from the grid | E26: Export as CSV downloaded 'Stores_07-21-2026.csv' | F26: Pass
B27: 9 | C27: Click new button | D27: New store modal should display | E27: New button opens New Store modal | F27: Pass
B28: 10 | C28: Click profile image section | D28: Should open file explorer | E28: Store profile-image control is native file input (invokes OS file picker) | F28: Pass
B29: 11 | C29: Select an image and click open button | D29: Selected image should reflect in profile image section | E29: Uploaded image reflected in store profile-image section | F29: Pass
B30: 12 | C30: Input name | D30: Inputted anme should reflect on the field | E30: Store name reflects 'RegressionTest StoreQA20260720' | F30: Pass
B31: 13 | C31: Input phone number | D31: Inputted phone number should reflect on the field | E31: Phone number reflects '(555) 123-4567' | F31: Pass
... B34: 16 | C34: Click save and close button | D34: 1. Modal should close 2. Success message should display 3. Created record should display in All Stores grid | E34: Store saved — toast 'Store successfully created', modal closed; store confirmed present in Stores grid (filter value dropdown + search both matched it in S4/S7) | F34: Pass
A36: Timeline | B36: 1 | C36: Click filter repair shops | D36: Filter dropdown should display | E36: Filter Activity dropdown displayed | F36: Pass
B37: 2 | C37: Click "Select a filter" field | D37: 1. Dropdown with options should display 2. Options displayed are the header columns on the grid | E37: Filter options = activity columns: ['Date', 'Action'] | F37: Pass
B38: 3 | C38: Verify if user able to select an option | D38: 1. Selected option should reflect on the field 2. "Select a value" field should display | E38: Selected 'Action'; 'Select a value' field displayed | F38: Pass
B39: 4 | C39: Click "Select a value" | D39: 1. Dropdown with option should display 2. Options displayed is dependent on what value is selected on the first field | E39: Value dropdown (dependent on 'Action'): ['Create Affiliate', 'Create Branch', 'Create Product', 'Create Shop', 'Create Store', 'Remove Product', 'Update Affiliate', 'Update Branch', 'Update Employee', 'Update Product', 'Update Registration', 'Update Shop'] | F39: Pass
B40: 5 | C40: Verify if user able to select a value | D40: 1.Selected value should reflect on the field 2. Selected value should reflect on the field 3. Add filter button should display | E40: Value 'Create Affiliate' selected; Add Filter button displayed | F40: Pass
B41: 6 | C41: Click Add Filter button | D41: Should create a new tab in users grid and should filter depending on the filter setup | E41: Add Filter applied (clicked) — activity grid filtered | F41: Pass
B42: 7 | C42: Verify if user is able to search | D42: User should be able to search | E42: Activity search accepts input and filters | F42: Pass
B43: 8 | C43: Verify if all actions, isertions, updates the user did on the record displayed in timeline tab | D43: Should create a record in timeline tab all the actions the user did | E43: Timeline logs user actions (create/update entries with timestamps present=True) | F43: Pass
A45: Notes | B45: 1 | C45: Verify if New button is working | D45: New note modal should display | E45: New button opens New Note modal | F45: Pass
B46: 2 | C46: Verify if user able to input in title field | D46: Should be able to input on the field | E46: Title field accepts input ('Regression Test Note') | F46: Pass
...

Sheet CLAIM REPORTS
A1: Module | B1: Scenario ID | C1: Test Description | D1: Expected Result | E1: Actual Result | F1: Notes/Remarks | G1: Defect ID
A2: Claim Reports | B2: 1 | C2: Verify if New button is working | D2: 1. New claim modal should display 2. Step 1 "Search Registration" should display | E2: New opens New Claim modal; Step 1 'Search Registration' displayed | F2: Pass
B3: 2 | C3: Verify if grid displayed | D3: All registrations should display | E3: Step 1 registrations grid displays (10 rows) | F3: Pass
B4: 3 | C4: Verify if able to search registration | D4: Should be able to search registration | E4: Search registration '798027154805' (match shown=True) | F4: Pass
B5: 4 | C5: Verify if able to select registration | D5: 1. Radio button should be pilled green 2. Next button should be enabled | E5: Registration selected (green radio pill); Next enabled=True | F5: Pass
B6: 5 | C6: Verify if Next button is working | D6: 1. Should route to step 2 2. If a selected registration has already a claim, an error should toast having a message "This registration has already been claimed" | E6: Next routed to Step 2 Product Details (already-claimed guard toasts when reg has a claim) | F6: Pass
B7: 6 | C7: Verify if Product Details in step 2 displayed | D7: Product Details should display: 1. Pin should display 2. Plan should display 3. Device should display 4. IMEI should display 5. Product Barcode should display 6. Product Name should display | E7: Step 2 Product Details shows: ['Pin', 'Plan', 'Device', 'IMEI', 'Barcode'] | F7: Pass
B8: 7 | C8: Click Next button | D8: Should route to Step 3 | E8: Routed to Step 3 Customer Details (present=True) | F8: Pass
B9: 8 | C9: Verify if Customer Details displayed | D9: 1. Customer details should display 2. Customer details should populate on the fields: -Email Address should populate on the field -First Name should populate -Last Name should populate -Country Code should populate -Phone Number should populate -Country should populate -Language should populate -Street should populate -Unit/Aprtment/Suite should populate -City should populate -Country should populate -Province should populate -Postal Code should populate -Notes field should populate | E9: Step 3 customer fields populated (first_name='Mujtaba', email/phone/address from registration) | F9: Pass
B10: 9 | C10: Verify if able to update customer details | D10: Should be able to update customer details | E10: DEVIATION: customer-detail fields are disabled/read-only in the wizard (and on the record's Customer Details tab) — cannot update. Contradicts expected 'should be able to update'. May be intended data-integrity behavior — flag for PM (not auto-filed). | F10: Fail
B11: 10 | C11: Click Next button | D11: Should route to step 4 | E11: Routed to Step 4 (final review step with Done button present=True) | F11: Pass
